<?xml version="1.0" encoding="utf-8"?>
<!-- This URDF was automatically created by SolidWorks to URDF Exporter! Originally created by Stephen Brawner (brawner@gmail.com) 
     Commit Version: 1.6.0-4-g7f85cfe  Build Version: 1.6.7995.38578
     For more information, please see http://wiki.ros.org/sw_urdf_exporter -->
<robot
  name="simbot_description">
  <link
    name="base_link">
    <inertial>
      <origin
        xyz="0.019 0.022 0.075"
        rpy="0 0 0" />
      <mass
        value="0.018147" />
      <inertia
        ixx="7.8262E-06"
        ixy="-2.8236E-08"
        ixz="-2.5734E-07"
        iyy="1.2262E-05"
        iyz="-4.9201E-08"
        izz="6.6825E-06" />
    </inertial>
    <visual>
      <origin
        xyz="0 0 0"
        rpy="0 0 0" />
      <geometry>
        <mesh
          filename="package://simbot_description/meshes/base_link.obj" />
      </geometry>
      <material
        name="">
        <color
          rgba="0.79216 0.81961 0.93333 1" />
      </material>
    </visual>
    <collision>
      <origin
        xyz="0 0 0"
        rpy="0 0 0" />
      <geometry>
        <mesh
          filename="package://simbot_description/meshes/base_link.obj" />
      </geometry>
    </collision>
  </link>
  <link
    name="wheel_right">
    <inertial>
      <origin
        xyz="5.40936892195337E-06 0.0053866273434393 1.77401586527737E-05"
        rpy="0 0 0" />
      <mass
        value="0.0045744445105682" />
      <inertia
        ixx="4.12952648526462E-07"
        ixy="2.53188566302057E-11"
        ixz="6.72430688651993E-11"
        iyy="7.92972035023719E-07"
        iyz="8.30338141117647E-11"
        izz="4.13152669920294E-07" />
    </inertial>
    <visual>
      <origin
        xyz="0 0 0"
        rpy="0 0 0" />
      <geometry>
        <mesh
          filename="package://simbot_description/meshes/wheel_right.obj" />
      </geometry>
      <material
        name="">
        <color
          rgba="0.6 0.6 0.6 1" />
      </material>
    </visual>
    <collision>
      <origin
        xyz="0 0 0"
        rpy="0 0 0" />
      <geometry>
        <mesh
          filename="package://simbot_description/meshes/wheel_right.obj" />
      </geometry>
    </collision>
  </link>
  <joint
    name="motor_right_wheel"
    type="continuous">
    <origin
      xyz="-0.018259 -0.064898 0.039989"
      rpy="-3.1416 -1.4054 -1.5701" />
    <parent
      link="base_link" />
    <child
      link="wheel_right" />
    <axis
      xyz="0 1 0" />
  </joint>
  <link
    name="wheel_left">
    <inertial>
      <origin
        xyz="5.40936892195337E-06 0.00538663068975814 1.77401586527598E-05"
        rpy="0 0 0" />
      <mass
        value="0.0045744445105682" />
      <inertia
        ixx="4.12952648526462E-07"
        ixy="2.53188566302724E-11"
        ixz="6.72430688652125E-11"
        iyy="7.92972035023719E-07"
        iyz="8.30338141120147E-11"
        izz="4.13152669920294E-07" />
    </inertial>
    <visual>
      <origin
        xyz="0 0 0"
        rpy="0 0 0" />
      <geometry>
        <mesh
          filename="package://simbot_description/meshes/wheel_left.obj" />
      </geometry>
      <material
        name="">
        <color
          rgba="0.6 0.6 0.6 1" />
      </material>
    </visual>
    <collision>
      <origin
        xyz="0 0 0"
        rpy="0 0 0" />
      <geometry>
        <mesh
          filename="package://simbot_description/meshes/wheel_left.obj" />
      </geometry>
    </collision>
  </link>
  <joint
    name="motor_left_wheel"
    type="continuous">
    <origin
      xyz="0.057497 -0.065299 0.039989"
      rpy="0 1.4357 -1.5706" />
    <parent
      link="base_link" />
    <child
      link="wheel_left" />
    <axis
      xyz="0 1 0" />
  </joint>
</robot>